// Test output.
import void testPrint(const ubyte * str, ...);

exception ExampleError(int value);

void throwFunction0() {
	try {
		testPrint(C"0: Throwing.");
		throw ExampleError(256);
	} catch (ExampleError error) {
		testPrint(C"0: Caught error with value %d.", error.value);
	}
}

void throwFunction1() {
	try {
		testPrint(C"1: Calling 0.");
		throwFunction0();
		testPrint(C"1: Successfully finished 0.");
		
		testPrint(C"1: Throwing.");
		throw ExampleError(512);
	} catch (ExampleError error) {
		testPrint(C"1: Caught error with value %d.", error.value);
	}
}

void throwFunction2() {
	try {
		testPrint(C"2: Calling 1.");
		throwFunction1();
		testPrint(C"2: Successfully finished 1.");
	} catch (ExampleError error) {
		testPrint(C"2: Caught error with value %d.", error.value);
	}
}

// Entry point.
export int testEntryPoint(unused int argc, unused ubyte ** argv) {
	throwFunction2();
	return 0;
}

